<sdf version='1.7'>
  <world name='default'>
    <light name='sun' type='directional'>
      <cast_shadows>1</cast_shadows>
      <pose>0 0 10 0 -0 0</pose>
      <diffuse>0.8 0.8 0.8 1</diffuse>
      <specular>0.2 0.2 0.2 1</specular>
      <attenuation>
        <range>1000</range>
        <constant>0.9</constant>
        <linear>0.01</linear>
        <quadratic>0.001</quadratic>
      </attenuation>
      <direction>-0.5 0.1 -0.9</direction>
      <spot>
        <inner_angle>0</inner_angle>
        <outer_angle>0</outer_angle>
        <falloff>0</falloff>
      </spot>
    </light>
    <model name='ground_plane'>
      <static>1</static>
      <link name='link'>
        <collision name='collision'>
          <geometry>
            <plane>
              <normal>0 0 1</normal>
              <size>100 100</size>
            </plane>
          </geometry>
          <surface>
            <contact>
              <collide_bitmask>65535</collide_bitmask>
              <ode/>
            </contact>
            <friction>
              <ode>
                <mu>100</mu>
                <mu2>50</mu2>
              </ode>
              <torsional>
                <ode/>
              </torsional>
            </friction>
            <bounce/>
          </surface>
          <max_contacts>10</max_contacts>
        </collision>
        <visual name='visual'>
          <cast_shadows>0</cast_shadows>
          <geometry>
            <plane>
              <normal>0 0 1</normal>
              <size>100 100</size>
            </plane>
          </geometry>
          <material>
            <script>
              <uri>file://media/materials/scripts/gazebo.material</uri>
              <name>Gazebo/Grey</name>
            </script>
          </material>
        </visual>
        <self_collide>0</self_collide>
        <enable_wind>0</enable_wind>
        <kinematic>0</kinematic>
      </link>
    </model>
    <gravity>0 0 -9.8</gravity>
    <magnetic_field>6e-06 2.3e-05 -4.2e-05</magnetic_field>
    <atmosphere type='adiabatic'/>
    <physics type='ode'>
      <max_step_size>0.001</max_step_size>
      <real_time_factor>1</real_time_factor>
      <real_time_update_rate>1000</real_time_update_rate>
    </physics>
    <scene>
      <ambient>0.4 0.4 0.4 1</ambient>
      <background>0.7 0.7 0.7 1</background>
      <shadows>1</shadows>
    </scene>
    <audio>
      <device>default</device>
    </audio>
    <wind/>
    <spherical_coordinates>
      <surface_model>EARTH_WGS84</surface_model>
      <latitude_deg>0</latitude_deg>
      <longitude_deg>0</longitude_deg>
      <elevation>0</elevation>
      <heading_deg>0</heading_deg>
    </spherical_coordinates>
    <model name='pinecone_robot'>
      <link name='base_link'>
        <inertial>
          <pose>-0.057357 0 0.066066 0 -0 0</pose>
          <mass>2.13</mass>
          <inertia>
            <ixx>0.0180887</ixx>
            <ixy>0</ixy>
            <ixz>-0.00051898</ixz>
            <iyy>0.0254291</iyy>
            <iyz>0</iyz>
            <izz>0.0318783</izz>
          </inertia>
        </inertial>
        <collision name='base_link_arduino_arm_collision'>
          <pose>-0.1429 0.00016 0.15665 3.14159 -0 0</pose>
          <geometry>
            <cylinder>
              <length>0.05469</length>
              <radius>0.0592</radius>
            </cylinder>
          </geometry>
          <max_contacts>10</max_contacts>
          <surface>
            <contact>
              <ode/>
            </contact>
            <bounce/>
            <friction>
              <torsional>
                <ode/>
              </torsional>
              <ode/>
            </friction>
          </surface>
        </collision>
        <collision name='base_link_fixed_joint_lump__chassis_collision_1'>
          <pose>-0.0585 0 0.059 0 -0 0</pose>
          <geometry>
            <box>
              <size>0.335 0.265 0.138</size>
            </box>
          </geometry>
          <surface>
            <contact>
              <ode/>
            </contact>
            <friction>
              <ode/>
              <torsional>
                <ode/>
              </torsional>
            </friction>
            <bounce/>
          </surface>
          <max_contacts>10</max_contacts>
        </collision>
        <collision name='base_link_fixed_joint_lump__caster_wheel_collision_2'>
          <pose>-0.151 0 -0.023 0 -0 0</pose>
          <geometry>
            <sphere>
              <radius>0.01</radius>
            </sphere>
          </geometry>
          <surface>
            <contact>
              <ode/>
            </contact>
            <friction>
              <ode>
                <mu>0.001</mu>
                <mu2>0.001</mu2>
              </ode>
              <torsional>
                <ode/>
              </torsional>
            </friction>
            <bounce/>
          </surface>
          <max_contacts>10</max_contacts>
        </collision>
        <collision name='base_link_fixed_joint_lump__imu_link_collision_3'>
          <pose>0.034 0 0.13 0 -0 0</pose>
          <geometry>
            <box>
              <size>0.05 0.05 0.05</size>
            </box>
          </geometry>
          <surface>
            <contact>
              <ode/>
            </contact>
            <friction>
              <ode/>
              <torsional>
                <ode/>
              </torsional>
            </friction>
            <bounce/>
          </surface>
          <max_contacts>10</max_contacts>
        </collision>
        <collision name='base_link_fixed_joint_lump__laser_frame_collision_4'>
          <pose>-0.026 0 0.202 0 -0 0</pose>
          <geometry>
            <cylinder>
              <length>0.04</length>
              <radius>0.05</radius>
            </cylinder>
          </geometry>
          <surface>
            <contact>
              <ode/>
            </contact>
            <friction>
              <ode/>
              <torsional>
                <ode/>
              </torsional>
            </friction>
            <bounce/>
          </surface>
          <max_contacts>10</max_contacts>
        </collision>
        <visual name='base_link_arduino_arm_visual'>
          <pose>-0.14 0 0.145 1.5708 -0 0</pose>
          <geometry>
            <mesh>
              <scale>0.00098 0.00098 0.00098</scale>
              <uri>file:///home/antonio/Documents/Projects/pinecone_pi4_ws/install/arduino_arm/share/arduino_arm/meshes/Base.stl</uri>
            </mesh>
          </geometry>
          <material>
            <script>
              <name>Gazebo/Green</name>
              <uri>file://media/materials/scripts/gazebo.material</uri>
            </script>
          </material>
        </visual>
        <visual name='base_link_fixed_joint_lump__chassis_visual_1'>
          <pose>-0.0585 0 0.059 0 -0 0</pose>
          <geometry>
            <box>
              <size>0.335 0.265 0.138</size>
            </box>
          </geometry>
          <material>
            <script>
              <name>Gazebo/Orange</name>
              <uri>file://media/materials/scripts/gazebo.material</uri>
            </script>
          </material>
        </visual>
        <visual name='base_link_fixed_joint_lump__camera_link_visual_2'>
          <pose>0.094 0 0.171 0 0.18 0</pose>
          <geometry>
            <box>
              <size>0.01 0.03 0.03</size>
            </box>
          </geometry>
          <material>
            <script>
              <name>Gazebo/Black</name>
              <uri>file://media/materials/scripts/gazebo.material</uri>
            </script>
          </material>
        </visual>
        <visual name='base_link_fixed_joint_lump__camera_link_visual_3'>
          <pose>0.085049 0 0.121808 0 0.18 0</pose>
          <geometry>
            <cylinder>
              <length>0.1</length>
              <radius>0.002</radius>
            </cylinder>
          </geometry>
          <material>
            <script>
              <name>Gazebo/Black</name>
              <uri>file://media/materials/scripts/gazebo.material</uri>
            </script>
          </material>
        </visual>
        <visual name='base_link_fixed_joint_lump__caster_wheel_visual_4'>
          <pose>-0.151 0 -0.023 0 -0 0</pose>
          <geometry>
            <sphere>
              <radius>0.01</radius>
            </sphere>
          </geometry>
          <material>
            <script>
              <name>Gazebo/White</name>
              <uri>file://media/materials/scripts/gazebo.material</uri>
            </script>
          </material>
        </visual>
        <visual name='base_link_fixed_joint_lump__face_link_visual_5'>
          <pose>0.109 0.05 0.069 3.14159 1.57079 3.14159</pose>
          <geometry>
            <cylinder>
              <length>0.002</length>
              <radius>0.01</radius>
            </cylinder>
          </geometry>
          <material>
            <script>
              <name>Gazebo/Black</name>
              <uri>file://media/materials/scripts/gazebo.material</uri>
            </script>
          </material>
        </visual>
        <visual name='base_link_fixed_joint_lump__face_link_visual_6'>
          <pose>0.109 -0.05 0.069 3.14159 1.57079 3.14159</pose>
          <geometry>
            <cylinder>
              <length>0.002</length>
              <radius>0.01</radius>
            </cylinder>
          </geometry>
          <material>
            <script>
              <name>Gazebo/Black</name>
              <uri>file://media/materials/scripts/gazebo.material</uri>
            </script>
          </material>
        </visual>
        <visual name='base_link_fixed_joint_lump__face_link_visual_7'>
          <pose>0.098 0 0.059 0 1.5 0</pose>
          <geometry>
            <cylinder>
              <length>0.02</length>
              <radius>0.05</radius>
            </cylinder>
          </geometry>
          <material>
            <script>
              <name>Gazebo/Black</name>
              <uri>file://media/materials/scripts/gazebo.material</uri>
            </script>
          </material>
        </visual>
        <visual name='base_link_fixed_joint_lump__imu_link_visual_8'>
          <pose>0.034 0 0.13 0 -0 0</pose>
          <geometry>
            <box>
              <size>0.025 0.025 0.015</size>
            </box>
          </geometry>
          <material>
            <script>
              <name>Gazebo/Red</name>
              <uri>file://media/materials/scripts/gazebo.material</uri>
            </script>
          </material>
        </visual>
        <visual name='base_link_fixed_joint_lump__laser_frame_visual_9'>
          <pose>-0.026 0 0.202 0 -0 0</pose>
          <geometry>
            <cylinder>
              <length>0.04</length>
              <radius>0.05</radius>
            </cylinder>
          </geometry>
          <material>
            <script>
              <name>Gazebo/Yellow</name>
              <uri>file://media/materials/scripts/gazebo.material</uri>
            </script>
          </material>
        </visual>
        <visual name='base_link_fixed_joint_lump__laser_frame_visual_10'>
          <pose>-0.026 0 0.152 0 -0 0</pose>
          <geometry>
            <cylinder>
              <length>0.1</length>
              <radius>0.01</radius>
            </cylinder>
          </geometry>
          <material>
            <script>
              <name>Gazebo/Yellow</name>
              <uri>file://media/materials/scripts/gazebo.material</uri>
            </script>
          </material>
        </visual>
        <sensor name='camera' type='camera'>
          <visualize>1</visualize>
          <update_rate>10</update_rate>
          <camera>
            <horizontal_fov>1.089</horizontal_fov>
            <image>
              <format>R8G8B8</format>
              <width>640</width>
              <height>480</height>
            </image>
            <clip>
              <near>0.05</near>
              <far>8</far>
            </clip>
          </camera>
          <plugin name='camera_controller' filename='libgazebo_ros_camera.so'>
            <frame_name>camera_link_optical</frame_name>
          </plugin>
          <pose>0.094 0 0.171 0 0.18 0</pose>
        </sensor>
        <gravity>1</gravity>
        <sensor name='twr_imu' type='imu'>
          <always_on>1</always_on>
          <update_rate>100</update_rate>
          <visualize>1</visualize>
          <imu>
            <angular_velocity>
              <x>
                <noise type='gaussian'>
                  <mean>0</mean>
                  <stddev>0.0002</stddev>
                </noise>
              </x>
              <y>
                <noise type='gaussian'>
                  <mean>0</mean>
                  <stddev>0.0002</stddev>
                </noise>
              </y>
              <z>
                <noise type='gaussian'>
                  <mean>0</mean>
                  <stddev>0.0002</stddev>
                </noise>
              </z>
            </angular_velocity>
            <linear_acceleration>
              <x>
                <noise type='gaussian'>
                  <mean>0</mean>
                  <stddev>0.017</stddev>
                </noise>
              </x>
              <y>
                <noise type='gaussian'>
                  <mean>0</mean>
                  <stddev>0.017</stddev>
                </noise>
              </y>
              <z>
                <noise type='gaussian'>
                  <mean>0</mean>
                  <stddev>0.017</stddev>
                </noise>
              </z>
            </linear_acceleration>
            <orientation>
              <x>
                <noise type='gaussian'>
                  <mean>0.0</mean>
                  <stddev>2e-3</stddev>
                </noise>
              </x>
              <y>
                <noise type='gaussian'>
                  <mean>0.0</mean>
                  <stddev>2e-3</stddev>
                </noise>
              </y>
              <z>
                <noise type='gaussian'>
                  <mean>0.0</mean>
                  <stddev>2e-3</stddev>
                </noise>
              </z>
            </orientation>
          </imu>
          <plugin name='two_wheeled_robot_imu' filename='libgazebo_ros_imu_sensor.so'>
            <initial_orientation_as_reference>0</initial_orientation_as_reference>
            <frame_name>imu_link</frame_name>
            <ros>
              <namespace>/imu</namespace>
              <remapping>~/out:=data</remapping>
            </ros>
          </plugin>
          <pose>0.034 0 0.13 0 -0 0</pose>
        </sensor>
        <sensor name='laser' type='ray'>
          <visualize>0</visualize>
          <update_rate>10</update_rate>
          <ray>
            <scan>
              <horizontal>
                <samples>360</samples>
                <min_angle>-3.14</min_angle>
                <max_angle>3.14</max_angle>
                <resolution>1</resolution>
              </horizontal>
              <vertical>
                <samples>1</samples>
                <min_angle>0</min_angle>
                <max_angle>0</max_angle>
              </vertical>
            </scan>
            <range>
              <min>0.3</min>
              <max>12</max>
            </range>
          </ray>
          <plugin name='laser_controller' filename='libgazebo_ros_ray_sensor.so'>
            <ros>
              <argument>~/out:=scan</argument>
            </ros>
            <output_type>sensor_msgs/LaserScan</output_type>
            <frame_name>laser_frame</frame_name>
          </plugin>
          <pose>-0.026 0 0.202 0 -0 0</pose>
        </sensor>
        <self_collide>0</self_collide>
        <enable_wind>0</enable_wind>
        <kinematic>0</kinematic>
      </link>
      <joint name='base_waist_joint' type='revolute'>
        <pose relative_to='base_link'>-0.14345 -1e-05 0.18949 0 -0 0</pose>
        <parent>base_link</parent>
        <child>waist_link</child>
        <axis>
          <xyz>0 0 1</xyz>
          <limit>
            <lower>-1.571</lower>
            <upper>1.571</upper>
            <effort>1000</effort>
            <velocity>1</velocity>
          </limit>
          <dynamics>
            <spring_reference>0</spring_reference>
            <spring_stiffness>0</spring_stiffness>
          </dynamics>
        </axis>
      </joint>
      <link name='waist_link'>
        <pose relative_to='base_waist_joint'>0 0 0 0 -0 0</pose>
        <inertial>
          <pose>0 0 0 0 -0 0</pose>
          <mass>0.001</mass>
          <inertia>
            <ixx>0.001</ixx>
            <ixy>0</ixy>
            <ixz>0</ixz>
            <iyy>0.001</iyy>
            <iyz>0</iyz>
            <izz>0.001</izz>
          </inertia>
        </inertial>
        <collision name='waist_link_collision'>
          <pose>0.00019 0 3e-05 1.5708 -0 0</pose>
          <geometry>
            <mesh>
              <scale>0.00392 0.00392 0.00392</scale>
              <uri>file:///home/antonio/Documents/Projects/pinecone_pi4_ws/install/arduino_arm/share/arduino_arm/meshes/Waist.001.stl</uri>
            </mesh>
          </geometry>
          <surface>
            <contact>
              <ode/>
            </contact>
            <friction>
              <ode/>
              <torsional>
                <ode/>
              </torsional>
            </friction>
            <bounce/>
          </surface>
          <max_contacts>10</max_contacts>
        </collision>
        <visual name='waist_link_visual'>
          <pose>0 0 0 1.5708 -0 0</pose>
          <geometry>
            <mesh>
              <scale>0.00098 0.00098 0.00098</scale>
              <uri>file:///home/antonio/Documents/Projects/pinecone_pi4_ws/install/arduino_arm/share/arduino_arm/meshes/Waist.stl</uri>
            </mesh>
          </geometry>
          <material>
            <script>
              <name>Gazebo/Green</name>
              <uri>file://media/materials/scripts/gazebo.material</uri>
            </script>
          </material>
        </visual>
        <self_collide>0</self_collide>
        <enable_wind>0</enable_wind>
        <kinematic>0</kinematic>
      </link>
      <joint name='shoulder_joint' type='revolute'>
        <pose relative_to='waist_link'>0.00396 0.01369 0.03521 1.5708 0.03778 1.5708</pose>
        <parent>waist_link</parent>
        <child>arm1_link</child>
        <axis>
          <xyz>0 0 1</xyz>
          <limit>
            <lower>-1.571</lower>
            <upper>1.571</upper>
            <effort>1000</effort>
            <velocity>1</velocity>
          </limit>
          <dynamics>
            <spring_reference>0</spring_reference>
            <spring_stiffness>0</spring_stiffness>
          </dynamics>
        </axis>
      </joint>
      <link name='arm1_link'>
        <pose relative_to='shoulder_joint'>0 0 0 0 -0 0</pose>
        <inertial>
          <pose>0 0 0 0 -0 0</pose>
          <mass>0.001</mass>
          <inertia>
            <ixx>0.001</ixx>
            <ixy>0</ixy>
            <ixz>0</ixz>
            <iyy>0.001</iyy>
            <iyz>0</iyz>
            <izz>0.001</izz>
          </inertia>
        </inertial>
        <collision name='arm1_link_collision'>
          <pose>-0.00032 0.05624 0.00439 0 -0 0</pose>
          <geometry>
            <box>
              <size>0.04221 0.16277 0.02051</size>
            </box>
          </geometry>
          <surface>
            <contact>
              <ode/>
            </contact>
            <friction>
              <ode/>
              <torsional>
                <ode/>
              </torsional>
            </friction>
            <bounce/>
          </surface>
          <max_contacts>10</max_contacts>
        </collision>
        <visual name='arm1_link_visual'>
          <pose>0 0 0 0 -0 0</pose>
          <geometry>
            <mesh>
              <scale>0.00098 0.00098 0.00098</scale>
              <uri>file:///home/antonio/Documents/Projects/pinecone_pi4_ws/install/arduino_arm/share/arduino_arm/meshes/Arm_01.stl</uri>
            </mesh>
          </geometry>
          <material>
            <script>
              <name>Gazebo/Green</name>
              <uri>file://media/materials/scripts/gazebo.material</uri>
            </script>
          </material>
        </visual>
        <self_collide>0</self_collide>
        <enable_wind>0</enable_wind>
        <kinematic>0</kinematic>
      </link>
      <joint name='elbow_joint' type='revolute'>
        <pose relative_to='arm1_link'>-7e-05 0.11689 -0.00792 3.14029 -3e-06 -3.10381</pose>
        <parent>arm1_link</parent>
        <child>arm2_link</child>
        <axis>
          <xyz>0 0 1</xyz>
          <limit>
            <lower>-1.57</lower>
            <upper>1.57</upper>
            <effort>1000</effort>
            <velocity>1</velocity>
          </limit>
          <dynamics>
            <spring_reference>0</spring_reference>
            <spring_stiffness>0</spring_stiffness>
          </dynamics>
        </axis>
      </joint>
      <link name='arm2_link'>
        <pose relative_to='elbow_joint'>0 0 0 0 -0 0</pose>
        <inertial>
          <pose>0 0 0 0 -0 0</pose>
          <mass>0.001</mass>
          <inertia>
            <ixx>0.001</ixx>
            <ixy>0</ixy>
            <ixz>0</ixz>
            <iyy>0.001</iyy>
            <iyz>0</iyz>
            <izz>0.001</izz>
          </inertia>
        </inertial>
        <collision name='arm2_link_collision'>
          <pose>-0.00436 0.05688 0.00738 -3.05843 -1.57079 3.14159</pose>
          <geometry>
            <box>
              <size>0.02681 0.16398 0.0384</size>
            </box>
          </geometry>
          <surface>
            <contact>
              <ode/>
            </contact>
            <friction>
              <ode/>
              <torsional>
                <ode/>
              </torsional>
            </friction>
            <bounce/>
          </surface>
          <max_contacts>10</max_contacts>
        </collision>
        <visual name='arm2_link_visual'>
          <pose>0 0 0 -3.05857 -1.57079 3.14159</pose>
          <geometry>
            <mesh>
              <scale>0.00098 0.00098 0.00098</scale>
              <uri>file:///home/antonio/Documents/Projects/pinecone_pi4_ws/install/arduino_arm/share/arduino_arm/meshes/Arm_02.stl</uri>
            </mesh>
          </geometry>
          <material>
            <script>
              <name>Gazebo/Green</name>
              <uri>file://media/materials/scripts/gazebo.material</uri>
            </script>
          </material>
        </visual>
        <self_collide>0</self_collide>
        <enable_wind>0</enable_wind>
        <kinematic>0</kinematic>
      </link>
      <joint name='wrist_joint' type='revolute'>
        <pose relative_to='arm2_link'>-0.0088 0.12752 -0.00487 3.12701 3e-06 -3.14159</pose>
        <parent>arm2_link</parent>
        <child>arm3_link</child>
        <axis>
          <xyz>0 0 1</xyz>
          <limit>
            <lower>-1.57</lower>
            <upper>1.57</upper>
            <effort>1000</effort>
            <velocity>1</velocity>
          </limit>
          <dynamics>
            <spring_reference>0</spring_reference>
            <spring_stiffness>0</spring_stiffness>
          </dynamics>
        </axis>
      </joint>
      <link name='arm3_link'>
        <pose relative_to='wrist_joint'>0 0 0 0 -0 0</pose>
        <inertial>
          <pose>0 0 0 0 -0 0</pose>
          <mass>0.0001</mass>
          <inertia>
            <ixx>0.001</ixx>
            <ixy>0</ixy>
            <ixz>0</ixz>
            <iyy>0.001</iyy>
            <iyz>0</iyz>
            <izz>0.001</izz>
          </inertia>
        </inertial>
        <collision name='arm3_link_collision'>
          <pose>-0.00062 0.00019 0.00049 1.24161 1.55752 1.5708</pose>
          <geometry>
            <mesh>
              <scale>1 1 1</scale>
              <uri>file:///home/antonio/Documents/Projects/pinecone_pi4_ws/install/arduino_arm/share/arduino_arm/meshes/Arm_03.001.stl</uri>
            </mesh>
          </geometry>
          <surface>
            <contact>
              <ode/>
            </contact>
            <friction>
              <ode/>
              <torsional>
                <ode/>
              </torsional>
            </friction>
            <bounce/>
          </surface>
          <max_contacts>10</max_contacts>
        </collision>
        <visual name='arm3_link_visual'>
          <pose>0 0 0 1.2416 1.55752 1.5708</pose>
          <geometry>
            <mesh>
              <scale>0.00098 0.00098 0.00098</scale>
              <uri>file:///home/antonio/Documents/Projects/pinecone_pi4_ws/install/arduino_arm/share/arduino_arm/meshes/Arm_03.stl</uri>
            </mesh>
          </geometry>
          <material>
            <script>
              <name>Gazebo/Green</name>
              <uri>file://media/materials/scripts/gazebo.material</uri>
            </script>
          </material>
        </visual>
        <self_collide>0</self_collide>
        <enable_wind>0</enable_wind>
        <kinematic>0</kinematic>
      </link>
      <joint name='gripper1_joint' type='revolute'>
        <pose relative_to='arm3_link'>-0.02735 0.03009 -0.02013 1.86728 -1.55751 -1.57079</pose>
        <parent>arm3_link</parent>
        <child>gripper1_link</child>
        <axis>
          <xyz>0 0 1</xyz>
          <limit>
            <lower>0</lower>
            <upper>1.047</upper>
            <effort>1000</effort>
            <velocity>1</velocity>
          </limit>
          <dynamics>
            <spring_reference>0</spring_reference>
            <spring_stiffness>0</spring_stiffness>
          </dynamics>
        </axis>
      </joint>
      <link name='gripper1_link'>
        <pose relative_to='gripper1_joint'>0 0 0 0 -0 0</pose>
        <inertial>
          <pose>0 0 0 0 -0 0</pose>
          <mass>0.0001</mass>
          <inertia>
            <ixx>0.001</ixx>
            <ixy>0</ixy>
            <ixz>0</ixz>
            <iyy>0.001</iyy>
            <iyz>0</iyz>
            <izz>0.001</izz>
          </inertia>
        </inertial>
        <collision name='gripper1_link_collision'>
          <pose>0 -0.01 0.014 -1.86728 0 0</pose>
          <geometry>
            <mesh>
              <scale>0.001 0.001 0.001</scale>
              <uri>file:///home/antonio/Documents/Projects/pinecone_pi4_ws/install/arduino_arm/share/arduino_arm/meshes/gripper1_fix.stl</uri>
            </mesh>
          </geometry>
          <surface>
            <contact>
              <ode/>
            </contact>
            <friction>
              <ode/>
              <torsional>
                <ode/>
              </torsional>
            </friction>
            <bounce/>
          </surface>
          <max_contacts>10</max_contacts>
        </collision>
        <visual name='gripper1_link_visual'>
          <pose>0 -0.01 0.014 -1.86728 0 0</pose>
          <geometry>
            <mesh>
              <scale>0.001 0.001 0.001</scale>
              <uri>file:///home/antonio/Documents/Projects/pinecone_pi4_ws/install/arduino_arm/share/arduino_arm/meshes/gripper1_fix.stl</uri>
            </mesh>
          </geometry>
          <material>
            <script>
              <name>Gazebo/Green</name>
              <uri>file://media/materials/scripts/gazebo.material</uri>
            </script>
          </material>
        </visual>
        <self_collide>0</self_collide>
        <enable_wind>0</enable_wind>
        <kinematic>0</kinematic>
      </link>
      <joint name='gripper2_joint' type='revolute'>
        <pose relative_to='arm3_link'>-0.02492 0.03048 0.00564 -1.25673 -1.55752 -1.57079</pose>
        <parent>arm3_link</parent>
        <child>gripper2_link</child>
        <axis>
          <xyz>0 0 1</xyz>
          <limit>
            <lower>0</lower>
            <upper>1.047</upper>
            <effort>1000</effort>
            <velocity>1</velocity>
          </limit>
          <dynamics>
            <spring_reference>0</spring_reference>
            <spring_stiffness>0</spring_stiffness>
          </dynamics>
        </axis>
      </joint>
      <link name='gripper2_link'>
        <pose relative_to='gripper2_joint'>0 0 0 0 -0 0</pose>
        <inertial>
          <pose>0 0 0 0 -0 0</pose>
          <mass>0.0001</mass>
          <inertia>
            <ixx>0.001</ixx>
            <ixy>0</ixy>
            <ixz>0</ixz>
            <iyy>0.001</iyy>
            <iyz>0</iyz>
            <izz>0.001</izz>
          </inertia>
        </inertial>
        <collision name='gripper2_link_collision'>
          <pose>-0.0015 0.01 -0.0165 1.25673 -0 0</pose>
          <geometry>
            <cylinder>
              <length>0.001</length>
              <radius>0.001</radius>
            </cylinder>
          </geometry>
          <surface>
            <contact>
              <ode/>
            </contact>
            <friction>
              <ode/>
              <torsional>
                <ode/>
              </torsional>
            </friction>
            <bounce/>
          </surface>
          <max_contacts>10</max_contacts>
        </collision>
        <visual name='gripper2_link_visual'>
          <pose>-0.0015 0.01 -0.0165 1.25673 -0 0</pose>
          <geometry>
            <mesh>
              <scale>0.001 0.001 0.001</scale>
              <uri>file:///home/antonio/Documents/Projects/pinecone_pi4_ws/install/arduino_arm/share/arduino_arm/meshes/gripper2_fix.stl</uri>
            </mesh>
          </geometry>
          <material>
            <script>
              <name>Gazebo/Green</name>
              <uri>file://media/materials/scripts/gazebo.material</uri>
            </script>
          </material>
        </visual>
        <self_collide>0</self_collide>
        <enable_wind>0</enable_wind>
        <kinematic>0</kinematic>
      </link>
      <joint name='left_wheel_joint' type='revolute'>
        <pose relative_to='base_link'>0 0.1485 0 -1.5708 0 0</pose>
        <parent>base_link</parent>
        <child>left_wheel</child>
        <axis>
          <xyz>0 0 1</xyz>
          <limit>
            <lower>-1e+16</lower>
            <upper>1e+16</upper>
          </limit>
          <dynamics>
            <spring_reference>0</spring_reference>
            <spring_stiffness>0</spring_stiffness>
          </dynamics>
        </axis>
      </joint>
      <link name='left_wheel'>
        <pose relative_to='left_wheel_joint'>0 0 0 0 -0 0</pose>
        <inertial>
          <pose>0 0 0 0 -0 0</pose>
          <mass>0.05</mass>
          <inertia>
            <ixx>1.64292e-05</ixx>
            <ixy>0</ixy>
            <ixz>0</ixz>
            <iyy>1.64292e-05</iyy>
            <iyz>0</iyz>
            <izz>2.7225e-05</izz>
          </inertia>
        </inertial>
        <collision name='left_wheel_collision'>
          <pose>0 0 0 0 -0 0</pose>
          <geometry>
            <sphere>
              <radius>0.033</radius>
            </sphere>
          </geometry>
          <surface>
            <contact>
              <ode/>
            </contact>
            <friction>
              <ode/>
              <torsional>
                <ode/>
              </torsional>
            </friction>
            <bounce/>
          </surface>
          <max_contacts>10</max_contacts>
        </collision>
        <visual name='left_wheel_visual'>
          <pose>0 0 0 0 -0 0</pose>
          <geometry>
            <cylinder>
              <length>0.026</length>
              <radius>0.033</radius>
            </cylinder>
          </geometry>
          <material>
            <script>
              <name>Gazebo/Blue</name>
              <uri>file://media/materials/scripts/gazebo.material</uri>
            </script>
          </material>
        </visual>
        <self_collide>0</self_collide>
        <enable_wind>0</enable_wind>
        <kinematic>0</kinematic>
      </link>
      <joint name='right_wheel_joint' type='revolute'>
        <pose relative_to='base_link'>0 -0.1485 0 1.5708 -0 0</pose>
        <parent>base_link</parent>
        <child>right_wheel</child>
        <axis>
          <xyz>0 0 -1</xyz>
          <limit>
            <lower>-1e+16</lower>
            <upper>1e+16</upper>
          </limit>
          <dynamics>
            <spring_reference>0</spring_reference>
            <spring_stiffness>0</spring_stiffness>
          </dynamics>
        </axis>
      </joint>
      <link name='right_wheel'>
        <pose relative_to='right_wheel_joint'>0 0 0 0 -0 0</pose>
        <inertial>
          <pose>0 0 0 0 -0 0</pose>
          <mass>0.05</mass>
          <inertia>
            <ixx>1.64292e-05</ixx>
            <ixy>0</ixy>
            <ixz>0</ixz>
            <iyy>1.64292e-05</iyy>
            <iyz>0</iyz>
            <izz>2.7225e-05</izz>
          </inertia>
        </inertial>
        <collision name='right_wheel_collision'>
          <pose>0 0 0 0 -0 0</pose>
          <geometry>
            <sphere>
              <radius>0.033</radius>
            </sphere>
          </geometry>
          <surface>
            <contact>
              <ode/>
            </contact>
            <friction>
              <ode/>
              <torsional>
                <ode/>
              </torsional>
            </friction>
            <bounce/>
          </surface>
          <max_contacts>10</max_contacts>
        </collision>
        <visual name='right_wheel_visual'>
          <pose>0 0 0 0 -0 0</pose>
          <geometry>
            <cylinder>
              <length>0.026</length>
              <radius>0.033</radius>
            </cylinder>
          </geometry>
          <material>
            <script>
              <name>Gazebo/Blue</name>
              <uri>file://media/materials/scripts/gazebo.material</uri>
            </script>
          </material>
        </visual>
        <self_collide>0</self_collide>
        <enable_wind>0</enable_wind>
        <kinematic>0</kinematic>
      </link>
      <static>0</static>
      <plugin name='gazebo_ros2_control' filename='libgazebo_ros2_control.so'>
        <parameters>/home/antonio/Documents/Projects/pinecone_pi4_ws/install/articubot_one/share/articubot_one/config/my_controllers.yaml</parameters>
        <parameters>/home/antonio/Documents/Projects/pinecone_pi4_ws/install/articubot_one/share/articubot_one/config/gaz_ros2_ctl_use_sim.yaml</parameters>
      </plugin>
      <pose>0 0 0 0 -0 0</pose>
    </model>
    <model name='beer'>
      <link name='link'>
        <pose>0 0 0.115 0 -0 0</pose>
        <inertial>
          <mass>0.39</mass>
          <inertia>
            <ixx>0.00058</ixx>
            <ixy>0</ixy>
            <ixz>0</ixz>
            <iyy>0.00058</iyy>
            <iyz>0</iyz>
            <izz>0.00019</izz>
          </inertia>
          <pose>0 0 0 0 -0 0</pose>
        </inertial>
        <collision name='collision'>
          <geometry>
            <cylinder>
              <radius>0.055</radius>
              <length>0.23</length>
            </cylinder>
          </geometry>
          <max_contacts>10</max_contacts>
          <surface>
            <contact>
              <ode/>
            </contact>
            <bounce/>
            <friction>
              <torsional>
                <ode/>
              </torsional>
              <ode/>
            </friction>
          </surface>
        </collision>
        <visual name='visual'>
          <geometry>
            <cylinder>
              <radius>0.055</radius>
              <length>0.23</length>
            </cylinder>
          </geometry>
          <material>
            <script>
              <uri>model://beer/materials/scripts</uri>
              <uri>model://beer/materials/textures</uri>
              <name>Beer/Diffuse</name>
            </script>
          </material>
        </visual>
        <self_collide>0</self_collide>
        <enable_wind>0</enable_wind>
        <kinematic>0</kinematic>
      </link>
      <pose>0.055185 -0.560023 0 0 -0 0</pose>
    </model>
    <model name='Construction Barrel'>
      <link name='link'>
        <inertial>
          <pose>0 0 0.4 0 -0 0</pose>
          <mass>500</mass>
          <inertia>
            <ixx>51.2096</ixx>
            <iyy>51.2096</iyy>
            <izz>25</izz>
            <ixy>0</ixy>
            <ixz>0</ixz>
            <iyz>0</iyz>
          </inertia>
        </inertial>
        <collision name='collision'>
          <geometry>
            <mesh>
              <uri>model://construction_barrel/meshes/construction_barrel.dae</uri>
            </mesh>
          </geometry>
          <max_contacts>10</max_contacts>
          <surface>
            <contact>
              <ode/>
            </contact>
            <bounce/>
            <friction>
              <torsional>
                <ode/>
              </torsional>
              <ode/>
            </friction>
          </surface>
        </collision>
        <visual name='visual'>
          <geometry>
            <mesh>
              <uri>model://construction_barrel/meshes/construction_barrel.dae</uri>
            </mesh>
          </geometry>
        </visual>
        <self_collide>0</self_collide>
        <enable_wind>0</enable_wind>
        <kinematic>0</kinematic>
      </link>
      <pose>0.190198 1.58444 0 0 -0 0</pose>
    </model>
    <model name='Construction Cone'>
      <link name='link'>
        <collision name='collision'>
          <geometry>
            <mesh>
              <scale>10 10 10</scale>
              <uri>model://construction_cone/meshes/construction_cone.dae</uri>
            </mesh>
          </geometry>
          <max_contacts>10</max_contacts>
          <surface>
            <contact>
              <ode/>
            </contact>
            <bounce/>
            <friction>
              <torsional>
                <ode/>
              </torsional>
              <ode/>
            </friction>
          </surface>
        </collision>
        <visual name='visual'>
          <geometry>
            <mesh>
              <scale>10 10 10</scale>
              <uri>model://construction_cone/meshes/construction_cone.dae</uri>
            </mesh>
          </geometry>
        </visual>
        <self_collide>0</self_collide>
        <inertial>
          <pose>0 0 0 0 -0 0</pose>
          <inertia>
            <ixx>1</ixx>
            <ixy>0</ixy>
            <ixz>0</ixz>
            <iyy>1</iyy>
            <iyz>0</iyz>
            <izz>1</izz>
          </inertia>
          <mass>1</mass>
        </inertial>
        <enable_wind>0</enable_wind>
        <kinematic>0</kinematic>
      </link>
      <pose>-2.14996 0.692167 0 0 -0 0</pose>
    </model>
    <state world_name='default'>
      <sim_time>8314 687000000</sim_time>
      <real_time>8229 923796606</real_time>
      <wall_time>1691876239 25177599</wall_time>
      <iterations>8226715</iterations>
      <model name='Construction Barrel'>
        <pose>0.190189 1.58444 -0 0 0 -4e-06</pose>
        <scale>1 1 1</scale>
        <link name='link'>
          <pose>0.190189 1.58444 -0 0 0 -4e-06</pose>
          <velocity>0 0 0 0 -0 0</velocity>
          <acceleration>1.28426 1.99029 1.37626 -1.83417 -0.069053 -3.14157</acceleration>
          <wrench>642.13 995.145 688.131 0 -0 0</wrench>
        </link>
      </model>
      <model name='Construction Cone'>
        <pose>-2.14996 0.692167 -0 0 -0 0</pose>
        <scale>1 1 1</scale>
        <link name='link'>
          <pose>-2.14996 0.692167 -0 0 -0 0</pose>
          <velocity>0 0 0 0 -0 0</velocity>
          <acceleration>0 -0 -0.008512 -2.58585 1.13682 3.14159</acceleration>
          <wrench>0 -0 -0.008512 0 -0 0</wrench>
        </link>
      </model>
      <model name='beer'>
        <pose>0.055185 -0.560023 -8e-06 -1e-06 -0 -4e-06</pose>
        <scale>1 1 1</scale>
        <link name='link'>
          <pose>0.055185 -0.560023 0.114992 -1e-06 -0 -4e-06</pose>
          <velocity>0 0 0 0 -0 0</velocity>
          <acceleration>0 0 -9.8 0 -0 0</acceleration>
          <wrench>0 0 -3.822 0 -0 0</wrench>
        </link>
      </model>
      <model name='ground_plane'>
        <pose>0 0 0 0 -0 0</pose>
        <scale>1 1 1</scale>
        <link name='link'>
          <pose>0 0 0 0 -0 0</pose>
          <velocity>0 0 0 0 -0 0</velocity>
          <acceleration>0 0 0 0 -0 0</acceleration>
          <wrench>0 0 0 0 -0 0</wrench>
        </link>
      </model>
      <model name='pinecone_robot'>
        <pose>-0.575343 -0.045392 0.033 0 2e-06 0.001256</pose>
        <scale>1 1 1</scale>
        <link name='arm1_link'>
          <pose>-0.732484 -0.041627 0.2577 -1.57089 1.53284 0.00024</pose>
          <velocity>0.003179 0.015494 -2.5e-05 7e-06 0.021717 -1.13189</velocity>
          <acceleration>-1.68403 -0.017355 -0.087808 0.091499 -1.45742 -0.009069</acceleration>
          <wrench>-0.001684 -1.7e-05 -8.8e-05 0 -0 0</wrench>
        </link>
        <link name='arm2_link'>
          <pose>-0.84929 -0.049586 0.253335 -1.57083 -0.056428 3.14062</pose>
          <velocity>-0.006001 0.1477 0.002511 3.13585 -1.533 2.00922</velocity>
          <acceleration>-1.68165 -0.015557 -0.258686 0.102547 -0.065072 -0.006289</acceleration>
          <wrench>-0.001682 -1.6e-05 -0.000259 0 -0 0</wrench>
        </link>
        <link name='arm3_link'>
          <pose>-0.847695 -0.044708 0.125457 -1.60129 1.07226 -0.026931</pose>
          <velocity>1.81226 0.146187 0.012216 3.12746 1.29086 1.77568</velocity>
          <acceleration>-1.65667 -0.004194 -0.267357 0.10276 -0.023783 -0.006302</acceleration>
          <wrench>-0.000166 -0 -2.7e-05 0 -0 0</wrench>
        </link>
        <link name='base_link'>
          <pose>-0.575343 -0.045392 0.033 0 2e-06 0.001256</pose>
          <velocity>-0.00013 2.5e-05 0.00079 3e-05 -0.005236 0.000169</velocity>
          <acceleration>-0.024945 -0.005901 0.966616 -3.07499 1.20807 -3.13714</acceleration>
          <wrench>-0.053134 -0.01257 2.05889 0 -0 0</wrench>
        </link>
        <link name='gripper1_link'>
          <pose>-0.887201 -0.064689 0.135391 -0.201991 0.007883 1.55739</pose>
          <velocity>1.80324 0.200283 0.085605 -2.36172 1.33133 -2.08555</velocity>
          <acceleration>-1.66329 -0.005055 -0.270588 0.072946 -0.023692 0.015316</acceleration>
          <wrench>-0.000166 -1e-06 -2.7e-05 0 -0 0</wrench>
        </link>
        <link name='gripper2_link'>
          <pose>-0.886378 -0.038956 0.132695 2.96116 -0.039132 1.30361</pose>
          <velocity>1.8334 0.199142 0.083744 3.13224 1.29112 1.75015</velocity>
          <acceleration>-1.67674 -0.005033 -0.268784 0.086924 -0.023574 0.016611</acceleration>
          <wrench>-0.000168 -1e-06 -2.7e-05 0 -0 0</wrench>
        </link>
        <link name='left_wheel'>
          <pose>-0.57553 0.103108 0.033 -1.57081 0.778557 0.00125</pose>
          <velocity>-0.00016 1.7e-05 0.000867 -0.000504 -0.004868 0.000169</velocity>
          <acceleration>0.671367 -0.00893 1.65921 -0.467553 0.088544 0.0077</acceleration>
          <wrench>0.033568 -0.000446 0.08296 0 -0 0</wrench>
        </link>
        <link name='right_wheel'>
          <pose>-0.575157 -0.193892 0.033 1.5708 -0.392531 0.001256</pose>
          <velocity>-0.000111 2e-05 0.000865 -0.000579 -0.003369 0.000167</velocity>
          <acceleration>0.672019 -0.006488 1.64652 -0.541402 0.993234 0.005134</acceleration>
          <wrench>0.033601 -0.000324 0.082326 0 -0 0</wrench>
        </link>
        <link name='waist_link'>
          <pose>-0.718793 -0.045582 0.22249 2e-06 -0 1.57112</pose>
          <velocity>-0.001107 -5e-06 4.6e-05 2.9e-05 -0.005227 -1.13189</velocity>
          <acceleration>-1.31313 -0.015463 0.057312 -3.04893 1.19933 3.13118</acceleration>
          <wrench>-0.001313 -1.5e-05 5.7e-05 0 -0 0</wrench>
        </link>
      </model>
      <light name='sun'>
        <pose>0 0 10 0 -0 0</pose>
      </light>
    </state>
    <gui fullscreen='0'>
      <camera name='user_camera'>
        <pose>-0.739259 -1.2056 0.519638 0 0.291643 1.52818</pose>
        <view_controller>orbit</view_controller>
        <projection_type>perspective</projection_type>
      </camera>
    </gui>
  </world>
</sdf>
