<?xml version="1.0" ?>
<!-- =================================================================================== -->
<!-- |    This document was autogenerated by xacro from ./src/articubot_one/description/robot.urdf.xacro | -->
<!-- |    EDITING THIS FILE BY HAND IS NOT RECOMMENDED                                 | -->
<!-- =================================================================================== -->
<robot name="robot">
  <!-- Specify some standard inertial calculations https://en.wikipedia.org/wiki/List_of_moments_of_inertia -->
  <!-- These make use of xacro's mathematical functionality -->
  <material name="white">
    <color rgba="1 1 1 1"/>
  </material>
  <material name="orange">
    <color rgba="1 0.3 0.1 1"/>
  </material>
  <material name="blue">
    <color rgba="0.2 0.2 1 1"/>
  </material>
  <material name="black">
    <color rgba="0 0 0 1"/>
  </material>
  <material name="red">
    <color rgba="1 0 0 1"/>
  </material>
  <material name="yellow">
    <color rgba="1 1 0 1"/>
  </material>
  <material name="green">
    <color rgba="0 1 0 1"/>
  </material>
  <material name="grey">
    <color rgba="0.2 0.2 0.2 1.0"/>
  </material>
  <material name="brown">
    <color rgba="0.8705882352941177 0.8117647058823529 0.7647058823529411 1.0"/>
  </material>
  <!-- BASE LINK -->
  <link name="base_link">

    </link>
  <!-- BASE_FOOTPRINT LINK -->
  <joint name="base_footprint_joint" type="fixed">
    <parent link="base_link"/>
    <child link="base_footprint"/>
    <origin rpy="0 0 0" xyz="0 0 0"/>
  </joint>
  <link name="base_footprint">
    </link>
  <!-- CHASSIS LINK -->
  <joint name="chassis_joint" type="fixed">
    <parent link="base_link"/>
    <child link="chassis"/>
    <origin xyz="-0.18 0 -0.01"/>
  </joint>
  <link name="chassis">
    <visual>
      <origin xyz="0.125 0 0.02"/>
      <geometry>
        <box size="0.25 0.125 0.04"/>
      </geometry>
      <material name="orange"/>
    </visual>
    <collision>
      <origin xyz="0.125 0 0.02"/>
      <geometry>
        <box size="0.25 0.125 0.04"/>
      </geometry>
    </collision>
    <inertial>
      <origin rpy="0 0 0" xyz="0.125 0 0.02"/>
      <mass value="2.0"/>
      <inertia ixx="0.0028708333333333333" ixy="0.0" ixz="0.0" iyy="0.010683333333333333" iyz="0.0" izz="0.013020833333333332"/>
    </inertial>
  </link>
  <gazebo reference="chassis">
    <material>Gazebo/Orange</material>
  </gazebo>
  <!-- <joint name="chassis_extension_joint" type="fixed">
        <parent link="chassis"/>
        <child link="chassis_extension"/>
        <origin xyz="${chassis_length} 0 ${wheel_radius}"/>
    </joint>

    <link name="chassis_extension">
        <visual>
            <origin xyz="${chassis_extension_length/2} 0 ${chassis_extension_height/2}"/>
            <geometry>
                <box size="${chassis_extension_length} ${chassis_width} ${chassis_extension_height}"/>
            </geometry>
            <material name="orange"/>
        </visual>
        <collision>
            <origin xyz="${chassis_extension_length/2} 0 ${chassis_extension_height/2}"/>
            <geometry>
                <box size="${chassis_extension_length} ${chassis_width} ${chassis_extension_height}"/>
            </geometry>
        </collision>
        <xacro:inertial_box mass="0.01" x="${chassis_extension_length}" y="${chassis_width}" z="${chassis_extension_height}">
            <origin xyz="${chassis_extension_length/2} 0 ${chassis_extension_height/2}" rpy="0 0 0"/>
        </xacro:inertial_box>
    </link>

    <gazebo reference="chassis_extension">
        <material>Gazebo/Orange</material>
    </gazebo> -->
  <!-- LEFT WHEEL LINK -->
  <joint name="left_wheel_joint" type="continuous">
    <parent link="base_link"/>
    <child link="left_wheel"/>
    <origin rpy="-1.5707963267948966 0 0" xyz="0 0.09 0"/>
    <axis xyz="0 0 1"/>
  </joint>
  <link name="left_wheel">
    <visual>
      <geometry>
        <cylinder length="0.026" radius="0.033"/>
      </geometry>
      <material name="blue"/>
    </visual>
    <visual>
      <origin rpy="0 0 0" xyz="0 0 -0.013"/>
      <geometry>
        <cylinder length="0.03" radius="0.005"/>
      </geometry>
      <material name="blue"/>
    </visual>
    <collision>
      <geometry>
        <sphere radius="0.033"/>
      </geometry>
    </collision>
    <inertial>
      <origin rpy="0 0 0" xyz="0 0 0"/>
      <mass value="0.05"/>
      <inertia ixx="1.642916666666667e-05" ixy="0.0" ixz="0.0" iyy="1.642916666666667e-05" iyz="0.0" izz="2.7225000000000004e-05"/>
    </inertial>
  </link>
  <gazebo reference="left_wheel">
    <material>Gazebo/Blue</material>
  </gazebo>
  <!-- RIGHT WHEEL LINK -->
  <joint name="right_wheel_joint" type="continuous">
    <parent link="base_link"/>
    <child link="right_wheel"/>
    <origin rpy="1.5707963267948966 0 0" xyz="0 -0.09 0"/>
    <axis xyz="0 0 -1"/>
  </joint>
  <link name="right_wheel">
    <visual>
      <geometry>
        <cylinder length="0.026" radius="0.033"/>
      </geometry>
      <material name="blue"/>
    </visual>
    <visual>
      <origin rpy="0 0 0" xyz="0 0 -0.013"/>
      <geometry>
        <cylinder length="0.03" radius="0.005"/>
      </geometry>
      <material name="blue"/>
    </visual>
    <collision>
      <geometry>
        <sphere radius="0.033"/>
      </geometry>
    </collision>
    <inertial>
      <origin rpy="0 0 0" xyz="0 0 0"/>
      <mass value="0.05"/>
      <inertia ixx="1.642916666666667e-05" ixy="0.0" ixz="0.0" iyy="1.642916666666667e-05" iyz="0.0" izz="2.7225000000000004e-05"/>
    </inertial>
  </link>
  <gazebo reference="right_wheel">
    <material>Gazebo/Blue</material>
  </gazebo>
  <!-- CASTER WHEEL LINK -->
  <joint name="caster_wheel_joint" type="fixed">
    <parent link="chassis"/>
    <child link="caster_wheel"/>
    <origin xyz="0.02 0 -0.008"/>
  </joint>
  <link name="caster_wheel">
    <visual>
      <geometry>
        <sphere radius="0.015"/>
      </geometry>
      <material name="blue"/>
    </visual>
    <collision>
      <geometry>
        <sphere radius="0.015"/>
      </geometry>
    </collision>
    <inertial>
      <origin rpy="0 0 0" xyz="0 0 0"/>
      <mass value="0.01"/>
      <inertia ixx="9e-07" ixy="0.0" ixz="0.0" iyy="9e-07" iyz="0.0" izz="9e-07"/>
    </inertial>
  </link>
  <gazebo reference="caster_wheel">
    <material>Gazebo/Blue</material>
    <mu1 value="0.001"/>
    <mu2 value="0.001"/>
  </gazebo>
  <ros2_control name="RealRobot" type="system">
    <hardware>
      <plugin>ros2_control_demo_example_2/DiffBotSystemHardware</plugin>
      <param name="example_param_hw_start_duration_sec">0</param>
      <param name="example_param_hw_stop_duration_sec">3.0</param>
    </hardware>
    <joint name="left_wheel_joint">
      <command_interface name="velocity"/>
      <state_interface name="position"/>
      <state_interface name="velocity"/>
    </joint>
    <joint name="right_wheel_joint">
      <command_interface name="velocity"/>
      <state_interface name="position"/>
      <state_interface name="velocity"/>
    </joint>
  </ros2_control>
  <ros2_control name="RealRobotArm" type="system">
    <hardware>
      <plugin>ros2_control_demo_example_1/RRBotSystemPositionOnlyHardware</plugin>
      <param name="example_param_hw_start_duration_sec">0</param>
      <param name="example_param_hw_stop_duration_sec">3.0</param>
      <param name="example_param_hw_slowdown">1.0</param>
    </hardware>
    <joint name="base_waist_joint">
      <command_interface name="position">
        <param name="min">-1</param>
        <param name="max">1</param>
      </command_interface>
      <state_interface name="position"/>
    </joint>
    <joint name="shoulder_joint">
      <command_interface name="position">
        <param name="min">-1</param>
        <param name="max">1</param>
      </command_interface>
      <state_interface name="position"/>
    </joint>
    <joint name="elbow_joint">
      <command_interface name="position">
        <param name="min">-1</param>
        <param name="max">1</param>
      </command_interface>
      <state_interface name="position"/>
    </joint>
    <joint name="wrist_joint">
      <command_interface name="position">
        <param name="min">-1</param>
        <param name="max">1</param>
      </command_interface>
      <state_interface name="position"/>
    </joint>
    <joint name="gripper1_joint">
      <command_interface name="position">
        <param name="min">-1</param>
        <param name="max">1</param>
      </command_interface>
      <state_interface name="position"/>
    </joint>
    <joint name="gripper2_joint">
      <command_interface name="position">
        <param name="min">-1</param>
        <param name="max">1</param>
      </command_interface>
      <state_interface name="position"/>
    </joint>
  </ros2_control>
  <gazebo>
    <plugin filename="libgazebo_ros2_control.so" name="gazebo_ros2_control">
      <parameters>/home/antonio/Documents/Projects/pinecone_pi4_ws/install/articubot_one/share/articubot_one/config/my_controllers.yaml</parameters>
      <parameters>/home/antonio/Documents/Projects/pinecone_pi4_ws/install/articubot_one/share/articubot_one/config/gaz_ros2_ctl_use_sim.yaml</parameters>
      <!-- <parameters>$(find arduino_arm_config)/config/ros2_controllers.yaml</parameters> -->
      <!-- <parameters>$(find articubot_one)/config/forward_position_publisher.yaml</parameters> -->
    </plugin>
  </gazebo>
  <joint name="laser_joint" type="fixed">
    <parent link="chassis"/>
    <child link="laser_frame"/>
    <origin rpy="0 0 0" xyz="0.025 0 0.10"/>
  </joint>
  <link name="laser_frame">
    <visual>
      <geometry>
        <cylinder length="0.04" radius="0.05"/>
      </geometry>
      <material name="yellow"/>
    </visual>
    <visual>
      <origin xyz="0 0 -0.05"/>
      <geometry>
        <cylinder length="0.1" radius="0.01"/>
      </geometry>
      <material name="yellow"/>
    </visual>
    <collision>
      <geometry>
        <cylinder length="0.04" radius="0.05"/>
      </geometry>
    </collision>
    <inertial>
      <origin rpy="0 0 0" xyz="0 0 0"/>
      <mass value="0.1"/>
      <inertia ixx="7.583333333333335e-05" ixy="0.0" ixz="0.0" iyy="7.583333333333335e-05" iyz="0.0" izz="0.00012500000000000003"/>
    </inertial>
  </link>
  <gazebo reference="laser_frame">
    <material>Gazebo/Yellow</material>
    <sensor name="laser" type="ray">
      <pose> 0 0 0 0 0 0 </pose>
      <visualize>false</visualize>
      <update_rate>10</update_rate>
      <ray>
        <scan>
          <horizontal>
            <samples>360</samples>
            <min_angle>-3.14</min_angle>
            <max_angle>3.14</max_angle>
          </horizontal>
        </scan>
        <range>
          <min>0.3</min>
          <max>12</max>
        </range>
      </ray>
      <plugin filename="libgazebo_ros_ray_sensor.so" name="laser_controller">
        <ros>
          <argument>~/out:=scan</argument>
        </ros>
        <output_type>sensor_msgs/LaserScan</output_type>
        <frame_name>laser_frame</frame_name>
      </plugin>
    </sensor>
  </gazebo>
  <joint name="camera_joint" type="fixed">
    <parent link="chassis"/>
    <child link="camera_link"/>
    <origin rpy="0 0 0" xyz="0.255 0 0.04"/>
  </joint>
  <link name="camera_link">
    <visual>
      <geometry>
        <box size="0.010 0.038 0.024"/>
      </geometry>
      <material name="black"/>
    </visual>
    <visual>
      <origin rpy="0 1.5707963267948966 0" xyz="0 0.016 0"/>
      <geometry>
        <cylinder length="0.01" radius="0.0122"/>
      </geometry>
      <material name="black"/>
    </visual>
    <visual>
      <origin rpy="0 1.5707963267948966 0" xyz="0 -0.016 0"/>
      <geometry>
        <cylinder length="0.01" radius="0.0122"/>
      </geometry>
      <material name="black"/>
    </visual>
    <!-- <visual>
            <origin xyz="0 0 -0.02"/>
            <geometry>
                <cylinder radius="0.002" length="0.06"/>
            </geometry>
            <material name="black"/>
        </visual> -->
    <collision>
      <geometry>
        <box size="0.001 0.001 0.001"/>
      </geometry>
    </collision>
  </link>
  <joint name="camera_optical_joint" type="fixed">
    <parent link="camera_link"/>
    <child link="camera_link_optical"/>
    <origin rpy="-1.5707963267948966 0 -1.5707963267948966" xyz="0 0 0"/>
  </joint>
  <link name="camera_link_optical"/>
  <gazebo reference="camera_link">
    <material>Gazebo/Black</material>
    <sensor name="camera" type="camera">
      <pose> 0 0 0 0 0 0 </pose>
      <visualize>true</visualize>
      <update_rate>10</update_rate>
      <camera>
        <horizontal_fov>1.089</horizontal_fov>
        <image>
          <format>R8G8B8</format>
          <width>640</width>
          <height>480</height>
        </image>
        <clip>
          <near>0.05</near>
          <far>8.0</far>
        </clip>
      </camera>
      <plugin filename="libgazebo_ros_camera.so" name="camera_controller">
        <frame_name>camera_link_optical</frame_name>
      </plugin>
    </sensor>
  </gazebo>
  <joint name="imu_joint" type="fixed">
    <parent link="chassis"/>
    <child link="imu_link"/>
    <origin rpy="0 0 0" xyz="0.08 0 0.045"/>
  </joint>
  <link name="imu_link">
    <visual>
      <geometry>
        <box size="0.03 0.03 0.015"/>
      </geometry>
      <material name="red"/>
    </visual>
    <collision>
      <geometry>
        <box size="0.05 0.05 0.05"/>
      </geometry>
    </collision>
    <inertial>
      <origin rpy="0 0 0" xyz="0 0 0"/>
      <mass value="0.01"/>
      <inertia ixx="4.166666666666667e-06" ixy="0.0" ixz="0.0" iyy="4.166666666666667e-06" iyz="0.0" izz="4.166666666666667e-06"/>
    </inertial>
  </link>
  <gazebo reference="imu_link">
    <material>Gazebo/Red</material>
    <gravity>true</gravity>
    <sensor name="twr_imu" type="imu">
      <always_on>true</always_on>
      <update_rate>100</update_rate>
      <visualize>true</visualize>
      <imu>
        <orientation>
          <x>
            <noise type="gaussian">
              <mean>0.0</mean>
              <stddev>2e-3</stddev>
            </noise>
          </x>
          <y>
            <noise type="gaussian">
              <mean>0.0</mean>
              <stddev>2e-3</stddev>
            </noise>
          </y>
          <z>
            <noise type="gaussian">
              <mean>0.0</mean>
              <stddev>2e-3</stddev>
            </noise>
          </z>
        </orientation>
        <angular_velocity>
          <x>
            <noise type="gaussian">
              <mean>0.0</mean>
              <stddev>2e-4</stddev>
            </noise>
          </x>
          <y>
            <noise type="gaussian">
              <mean>0.0</mean>
              <stddev>2e-4</stddev>
            </noise>
          </y>
          <z>
            <noise type="gaussian">
              <mean>0.0</mean>
              <stddev>2e-4</stddev>
            </noise>
          </z>
        </angular_velocity>
        <linear_acceleration>
          <x>
            <noise type="gaussian">
              <mean>0.0</mean>
              <stddev>1.7e-2</stddev>
            </noise>
          </x>
          <y>
            <noise type="gaussian">
              <mean>0.0</mean>
              <stddev>1.7e-2</stddev>
            </noise>
          </y>
          <z>
            <noise type="gaussian">
              <mean>0.0</mean>
              <stddev>1.7e-2</stddev>
            </noise>
          </z>
        </linear_acceleration>
      </imu>
      <plugin filename="libgazebo_ros_imu_sensor.so" name="two_wheeled_robot_imu">
        <initial_orientation_as_reference>false</initial_orientation_as_reference>
        <frame_name>imu_link</frame_name>
        <ros>
          <namespace>/imu</namespace>
          <remapping>~/out:=data</remapping>
        </ros>
      </plugin>
    </sensor>
  </gazebo>
  <!-- <xacro:include filename="depth_camera.xacro" /> -->
  <!-- <xacro:include filename="face.xacro" /> -->
  <!-- <?xml version="1.0"?> -->
  <!-- created with Phobos 1.0.1 "Capricious Choutengan" -->
  <!-- <robot name="arduino_arm"> -->
  <!-- <link name="base_link"/> -->
  <joint name="base_link_arduino_arm_joint" type="fixed">
    <parent link="chassis"/>
    <child link="base_link_arduino_arm"/>
    <origin rpy="0 0 0" xyz="0.18 0 0.056"/>
  </joint>
  <link name="base_link_arduino_arm">
    <inertial>
      <origin rpy="0 0 0" xyz="0 0 0"/>
      <mass value="0.01"/>
      <inertia ixx="0.001" ixy="0" ixz="0" iyy="0.001" iyz="0" izz="0.001"/>
    </inertial>
    <visual>
      <origin rpy="1.5708 0 0" xyz="0 0 0"/>
      <geometry>
        <mesh filename="file:///home/antonio/Documents/Projects/pinecone_pi4_ws/install/arduino_arm/share/arduino_arm/meshes/Base.stl" scale="0.00098 0.00098 0.00098"/>
      </geometry>
      <material name="">
        <color rgba="0 1 0 1"/>
      </material>
    </visual>
    <collision>
      <origin rpy="3.14159 0 0" xyz="-0.0029 0.00016 0.01165"/>
      <geometry>
        <cylinder length="0.05469" radius="0.0592"/>
      </geometry>
    </collision>
  </link>
  <link name="waist_link">
    <inertial>
      <origin rpy="0 0 0" xyz="0 0 0"/>
      <mass value="0.001"/>
      <inertia ixx="0.001" ixy="0" ixz="0" iyy="0.001" iyz="0" izz="0.001"/>
    </inertial>
    <visual>
      <origin rpy="1.5708 0 0" xyz="0 0 0"/>
      <geometry>
        <mesh filename="file:///home/antonio/Documents/Projects/pinecone_pi4_ws/install/arduino_arm/share/arduino_arm/meshes/Waist.stl" scale="0.00098 0.00098 0.00098"/>
      </geometry>
      <material name="">
        <color rgba="0 1 0 1"/>
      </material>
    </visual>
    <collision>
      <origin rpy="1.5708 0 0" xyz="0.00019 0 3e-05"/>
      <geometry>
        <mesh filename="file:///home/antonio/Documents/Projects/pinecone_pi4_ws/install/arduino_arm/share/arduino_arm/meshes/Waist.001.stl" scale="0.00392 0.00392 0.00392"/>
      </geometry>
    </collision>
  </link>
  <link name="arm1_link">
    <inertial>
      <origin rpy="0 0 0" xyz="0 0 0"/>
      <mass value="0.001"/>
      <inertia ixx="0.001" ixy="0" ixz="0" iyy="0.001" iyz="0" izz="0.001"/>
    </inertial>
    <visual>
      <origin rpy="0 0 0" xyz="0 0 0"/>
      <geometry>
        <mesh filename="file:///home/antonio/Documents/Projects/pinecone_pi4_ws/install/arduino_arm/share/arduino_arm/meshes/Arm_01.stl" scale="0.00098 0.00098 0.00098"/>
      </geometry>
      <material name="">
        <color rgba="0 1 0 1"/>
      </material>
    </visual>
    <collision>
      <origin rpy="0 0 0" xyz="-0.00032 0.05624 0.00439"/>
      <geometry>
        <box size="0.04221 0.16277 0.02051"/>
      </geometry>
    </collision>
  </link>
  <link name="arm2_link">
    <inertial>
      <origin rpy="0 0 0" xyz="0 0 0"/>
      <mass value="0.001"/>
      <inertia ixx="0.001" ixy="0" ixz="0" iyy="0.001" iyz="0" izz="0.001"/>
    </inertial>
    <visual>
      <origin rpy="-1.48894 -1.57209 1.57067" xyz="0 0 0"/>
      <geometry>
        <mesh filename="file:///home/antonio/Documents/Projects/pinecone_pi4_ws/install/arduino_arm/share/arduino_arm/meshes/Arm_02.stl" scale="0.00098 0.00098 0.00098"/>
      </geometry>
      <material name="">
        <color rgba="0 1 0 1"/>
      </material>
    </visual>
    <collision>
      <origin rpy="-1.48879 -1.57209 1.57066" xyz="-0.00436 0.05688 0.00738"/>
      <geometry>
        <box size="0.02681 0.16398 0.0384"/>
      </geometry>
    </collision>
  </link>
  <link name="arm3_link">
    <inertial>
      <origin rpy="0 0 0" xyz="0 0 0"/>
      <mass value="0.0001"/>
      <inertia ixx="0.001" ixy="0" ixz="0" iyy="0.001" iyz="0" izz="0.001"/>
    </inertial>
    <visual>
      <origin rpy="1.2416 1.55752 1.5708" xyz="0 0 0"/>
      <geometry>
        <mesh filename="file:///home/antonio/Documents/Projects/pinecone_pi4_ws/install/arduino_arm/share/arduino_arm/meshes/Arm_03.stl" scale="0.00098 0.00098 0.00098"/>
      </geometry>
      <material name="">
        <color rgba="0 1 0 1"/>
      </material>
    </visual>
    <collision>
      <origin rpy="1.24161 1.55752 1.5708" xyz="-0.00062 0.00019 0.00049"/>
      <geometry>
        <mesh filename="file:///home/antonio/Documents/Projects/pinecone_pi4_ws/install/arduino_arm/share/arduino_arm/meshes/Arm_03.001.stl" scale="1.0 1.0 1.0"/>
      </geometry>
    </collision>
  </link>
  <link name="gripper1_link">
    <inertial>
      <origin rpy="0 0 0" xyz="0 0 0"/>
      <mass value="0.0001"/>
      <inertia ixx="0.001" ixy="0" ixz="0" iyy="0.001" iyz="0" izz="0.001"/>
    </inertial>
    <visual>
      <origin rpy="-1.86728 0 0" xyz="0 -0.01 0.014"/>
      <geometry>
        <mesh filename="file:///home/antonio/Documents/Projects/pinecone_pi4_ws/install/arduino_arm/share/arduino_arm/meshes/gripper1_fix.stl" scale="0.001 0.001 0.001"/>
      </geometry>
      <material name="">
        <color rgba="0 1 1 1"/>
      </material>
    </visual>
    <collision>
      <origin rpy="-1.86728 0 0" xyz="0 -0.01 0.014"/>
      <geometry>
        <mesh filename="file:///home/antonio/Documents/Projects/pinecone_pi4_ws/install/arduino_arm/share/arduino_arm/meshes/gripper1_fix.stl" scale="0.001 0.001 0.001"/>
      </geometry>
    </collision>
  </link>
  <link name="gripper2_link">
    <inertial>
      <origin rpy="0 0 0" xyz="0 0 0"/>
      <mass value="0.0001"/>
      <inertia ixx="0.001" ixy="0" ixz="0" iyy="0.001" iyz="0" izz="0.001"/>
    </inertial>
    <visual>
      <origin rpy="1.25673 0 0" xyz="-0.0015 0.01 -0.0165"/>
      <geometry>
        <mesh filename="file:///home/antonio/Documents/Projects/pinecone_pi4_ws/install/arduino_arm/share/arduino_arm/meshes/gripper2_fix.stl" scale="0.001 0.001 0.001"/>
      </geometry>
      <material name="">
        <color rgba="0 1 1 1"/>
      </material>
    </visual>
    <collision>
      <origin rpy="1.25673 0 0" xyz="-0.0015 0.01 -0.0165"/>
      <geometry>
        <mesh filename="file:///home/antonio/Documents/Projects/pinecone_pi4_ws/install/arduino_arm/share/arduino_arm/meshes/gripper2_fix.stl" scale="0.001 0.001 0.001"/>
      </geometry>
      <!-- <geometry>
                <cylinder length="0.001" radius="0.001" />
            </geometry> -->
    </collision>
  </link>
  <joint name="base_waist_joint" type="revolute">
    <origin rpy="0 0 -1.5708" xyz="-0.00345 -1e-05 0.04449"/>
    <parent link="base_link_arduino_arm"/>
    <child link="waist_link"/>
    <axis xyz="0 0 1.0"/>
    <limit effort="1000.0" lower="-1.571" upper="1.571" velocity="1.0"/>
  </joint>
  <joint name="shoulder_joint" type="revolute">
    <origin rpy="1.5708 -0.022 1.5708" xyz="0.00396 0.01369 0.03521"/>
    <parent link="waist_link"/>
    <child link="arm1_link"/>
    <axis xyz="0 0 1.0"/>
    <limit effort="1000.0" lower="-1.571" upper="1.571" velocity="1.0"/>
  </joint>
  <joint name="elbow_joint" type="revolute">
    <origin rpy="-0.0013 -3.14159 -1.45" xyz="-7e-05 0.11689 -0.00792"/>
    <parent link="arm1_link"/>
    <child link="arm2_link"/>
    <axis xyz="0 0 1.0"/>
    <limit effort="1000.0" lower="-1.57" upper="1.57" velocity="1.0"/>
  </joint>
  <joint name="wrist_joint" type="revolute">
    <origin rpy="-0.01458 3.14159 1.5708" xyz="-0.0088 0.12752 -0.00487"/>
    <parent link="arm2_link"/>
    <child link="arm3_link"/>
    <axis xyz="0 0 1.0"/>
    <limit effort="1000.0" lower="-1.57" upper="1.57" velocity="1.0"/>
  </joint>
  <joint name="gripper1_joint" type="revolute">
    <origin rpy="-1.27431 -1.58408 1.5708" xyz="-0.02735 0.03009 -0.02013"/>
    <parent link="arm3_link"/>
    <child link="gripper1_link"/>
    <axis xyz="0 0 1.0"/>
    <limit effort="1000.0" lower="0" upper="1.047" velocity="1.0"/>
  </joint>
  <joint name="gripper2_joint" type="revolute">
    <origin rpy="-1.25673 -1.55752 -1.57079" xyz="-0.02492 0.03048 0.00564"/>
    <parent link="arm3_link"/>
    <child link="gripper2_link"/>
    <axis xyz="0 0 1.0"/>
    <limit effort="1000.0" lower="0" upper="1.047" velocity="1.0"/>
    <!-- <mimic joint="gripper1_joint" multiplier="1.0" offset="0.0" /> -->
  </joint>
  <transmission name="trans_base_joint">
    <type>transmission_interface/SimpleTransmission</type>
    <joint name="base_joint">
      <hardwareInterface>hardware_interface/PositionJointInterface</hardwareInterface>
    </joint>
    <actuator name="base_joint_motor">
      <hardwareInterface>hardware_interface/PositionJointInterface</hardwareInterface>
      <mechanicalReduction>1</mechanicalReduction>
    </actuator>
  </transmission>
  <transmission name="trans_shoulder">
    <type>transmission_interface/SimpleTransmission</type>
    <joint name="shoulder_joint">
      <hardwareInterface>hardware_interface/PositionJointInterface</hardwareInterface>
    </joint>
    <actuator name="shoulder_motor">
      <hardwareInterface>hardware_interface/PositionJointInterface</hardwareInterface>
      <mechanicalReduction>1</mechanicalReduction>
    </actuator>
  </transmission>
  <transmission name="trans_elbow">
    <type>transmission_interface/SimpleTransmission</type>
    <joint name="elbow_joint">
      <hardwareInterface>hardware_interface/PositionJointInterface</hardwareInterface>
    </joint>
    <actuator name="elbow_motor">
      <hardwareInterface>hardware_interface/PositionJointInterface</hardwareInterface>
      <mechanicalReduction>1</mechanicalReduction>
    </actuator>
  </transmission>
  <transmission name="trans_wrist">
    <type>transmission_interface/SimpleTransmission</type>
    <joint name="wrist_joint">
      <hardwareInterface>hardware_interface/PositionJointInterface</hardwareInterface>
    </joint>
    <actuator name="wrist_motor">
      <hardwareInterface>hardware_interface/PositionJointInterface</hardwareInterface>
      <mechanicalReduction>1</mechanicalReduction>
    </actuator>
  </transmission>
  <transmission name="trans_gripper">
    <type>transmission_interface/SimpleTransmission</type>
    <joint name="gripper1_joint">
      <hardwareInterface>hardware_interface/PositionJointInterface</hardwareInterface>
    </joint>
    <actuator name="gripper_motor">
      <hardwareInterface>hardware_interface/PositionJointInterface</hardwareInterface>
      <mechanicalReduction>1</mechanicalReduction>
    </actuator>
  </transmission>
  <!--
    <transmission name="trans_gripper2">
        <type>transmission_interface/SimpleTransmission</type>
        <joint name="gripper2_joint">
            <hardwareInterface>hardware_interface/EffortJointInterface</hardwareInterface>
        </joint>
        <actuator name="gripper2_motor">
            <hardwareInterface>hardware_interface/EffortJointInterface</hardwareInterface>
            <mechanicalReduction>1</mechanicalReduction>
        </actuator>
    </transmission>

    <gazebo>
        <plugin name="gazebo_ros2_control" filename="libgazebo_ros2_control.so">
            <robotNamespace>/</robotNamespace>
        </plugin>
    </gazebo>
-->
  <gazebo reference="base_link_arduino_arm">
    <material>Gazebo/White</material>
  </gazebo>
  <gazebo reference="waist_link">
    <material>Gazebo/Green</material>
  </gazebo>
  <gazebo reference="arm1_link">
    <material>Gazebo/Green</material>
  </gazebo>
  <gazebo reference="arm2_link">
    <material>Gazebo/Green</material>
  </gazebo>
  <gazebo reference="arm3_link">
    <material>Gazebo/White</material>
  </gazebo>
  <gazebo reference="gripper1_link">
    <material>Gazebo/White</material>
  </gazebo>
  <gazebo reference="gripper2_link">
    <material>Gazebo/White</material>
  </gazebo>

  <group name="manipulator">
    <joint name="base_waist_joint"/>
    <joint name="shoulder_joint"/>
    <joint name="elbow_joint"/>
    <joint name="wrist_joint"/>
  </group>
  <group name="gripper">
    <joint name="gripper_link1"/>
    <joint name="gripper_link1"/>
  </group>
  <group name="mobile_base">
    <joint name="planar_joint" /> <!-- planar_joint must have planar type -->
  </group>
  <group name="mobile_base_manipulator">
    <group name="manipulator" />
    <group name="gripper" />
    <group name="mobile_base" />
  </group>

</robot>
