<?xml version="1.0"?>
<robot xmlns:xacro="http://www.ros.org/wiki/xacro">

  <link name="arm_base">
    <inertial>
      <origin
        xyz="0 0 0"
        rpy="0 0 0" />
      <mass
        value="0.01" />
      <inertia
        ixx="0.00552196561445819"
        ixy="7.9550614501301E-10"
        ixz="-1.34378458924839E-09"
        iyy="0.00352397447953875"
        iyz="-1.10071809773382E-08"
        izz="0.00553739792746489" />
    </inertial>
    <visual>
      <origin
        xyz="0 0 0"
        rpy="0 0 0" />
      <geometry>

   
          <cylinder radius="0.05" length="0.04"/>  
          <!--   
        <mesh
          filename="file:/home/antonio/Documents/Projects/pinecone_pi4_ws/src/articubot_one/meshes/arm_base.dae" />
-->
      </geometry>
      <material name="green" />
    </visual>
    <collision>
      <origin
        xyz="0 0 0"
        rpy="0 0 0" />
      <geometry>
        <mesh
          filename="file:/home/antonio/Documents/Projects/pinecone_pi4_ws/src/articubot_one/meshes/arm_base.stl" />
      </geometry>
    </collision>
  </link>

  <link name="bicep">
    <inertial>
      <origin
        xyz="0.12821 3.5589E-06 0.052492"
        rpy="0 0 0" />
      <mass
        value="0.008" />
      <inertia
        ixx="0.0012474"
        ixy="-5.4004E-07"
        ixz="-0.0013148"
        iyy="0.0072923"
        iyz="-1.8586E-07"
        izz="0.0068178" />
    </inertial>
    <visual>
      <origin
        xyz="0 0 0"
        rpy="0 -1.5708 0" />
      <geometry>
        <mesh
          filename="file:/home/antonio/Documents/Projects/pinecone_pi4_ws/src/articubot_one/meshes/bicep.stl" />
      </geometry>
      <material name="green" />
    </visual>
    <collision>
      <origin
        xyz="0 0 0"
        rpy="0 -1.5708 0" />
      <geometry>
        <mesh
          filename="file:/home/antonio/Documents/Projects/pinecone_pi4_ws/src/articubot_one/meshes/bicep.stl" />
      </geometry>
    </collision>
  </link>


  <link
    name="bottom_wrist">
    <inertial>
      <origin
        xyz="-9.1053E-08 -0.069257 -1.86629999995759E-07"
        rpy="0 0 0" />
      <mass
        value="0.005" />
      <inertia
        ixx="0.00104290750143942"
        ixy="4.37155302268076E-09"
        ixz="-2.45049603914627E-09"
        iyy="0.000380518373895034"
        iyz="-7.56009835172156E-09"
        izz="0.00106006525067445" />
    </inertial>
    <visual>
      <origin
        xyz="0 0 0.13522"
        rpy="3.14 0 1.5708" />
      <geometry>
        <mesh
          filename="file:/home/antonio/Documents/Projects/pinecone_pi4_ws/src/articubot_one/meshes/wrist.stl" />
      </geometry>
      <material name="green" />
    </visual>
    <collision>
      <origin
        xyz="0 0 0.13522"
        rpy="3.14 0 1.5708" />
      <geometry>
        <mesh
          filename="file:/home/antonio/Documents/Projects/pinecone_pi4_ws/src/articubot_one/meshes/wrist.stl" />
      </geometry>
    </collision>
  </link>

  <link name="elbow">
    <inertial>
      <origin
        xyz="-0.11109 1.1476E-08 0.046469"
        rpy="0 0 0" />
      <mass
        value="0.004" />
      <inertia
        ixx="0.00079656"
        ixy="-7.8011E-10"
        ixz="0.00053616"
        iyy="0.003576"
        iyz="4.6326E-10"
        izz="0.0033698" />
    </inertial>
    <visual>
      <origin
        xyz="0.0 0.05163 0.20994"
        rpy="0 -1.5708 0" />
      <geometry>
        <mesh
          filename="file:/home/antonio/Documents/Projects/pinecone_pi4_ws/src/articubot_one/meshes/elbow.stl" />
      </geometry>
      <material name="green" />
    </visual>
    <collision>
      <origin
        xyz="0.0 0.05163 0.20994"
        rpy="0 -1.5708 0" />
      <geometry>
        <mesh
          filename="file:/home/antonio/Documents/Projects/pinecone_pi4_ws/src/articubot_one/meshes/elbow.stl" />
      </geometry>
    </collision>
  </link>

  <link
    name="top_wrist">
    <inertial>
      <origin
        xyz="-9.1053E-08 -0.069257 -1.86629999995759E-07"
        rpy="0 0 0" />
      <mass
        value="0.003" />
      <inertia
        ixx="0.00104290750143942"
        ixy="4.37155302268076E-09"
        ixz="-2.45049603914627E-09"
        iyy="0.000380518373895034"
        iyz="-7.56009835172156E-09"
        izz="0.00106006525067445" />
    </inertial>
    <visual>
      <origin
        xyz="0 0 0.13522"
        rpy="3.14 0 1.5708" />
      <geometry>
        <mesh
          filename="file:/home/antonio/Documents/Projects/pinecone_pi4_ws/src/articubot_one/meshes/wrist.stl" />
      </geometry>
      <material name="green" />
    </visual>
    <collision>
      <origin
        xyz="0 0 0.13522"
        rpy="3.14 0 1.5708" />
      <geometry>
        <mesh
          filename="file:/home/antonio/Documents/Projects/pinecone_pi4_ws/src/articubot_one/meshes/wrist.stl" />
      </geometry>
    </collision>
  </link>

  <!--######################################################################-->
  <joint name="arm_base_joint" type="continuous">
    <axis xyz="0 0 1" />
    <parent link="base_link" />
    <child link="arm_base" />
    <origin xyz="-0.16 0 0.12" rpy="0 0 0" />
  </joint>

  <joint name="shoulder_joint" type="continuous">
    <axis xyz="0 1 0" />
    <parent link="arm_base" />
    <child link="bicep" />
    <origin rpy="0 0 1.5708" xyz="-0.05166 0.0 0.20271" />
  </joint>

  <joint name="bottom_wrist_joint" type="continuous">
    <axis xyz="0 1 0" />
    <parent link="bicep" />
    <child link="bottom_wrist" />
    <origin rpy="0 0 0" xyz="0.0 -0.05194 0.269" />
  </joint>

  <joint name="elbow_joint" type="continuous">
    <axis xyz="0 0 1" />
    <parent link="bottom_wrist" />
    <child link="elbow" />
    <origin rpy="0 0 0" xyz="0.0 0 0.13522" />
  </joint>

  <joint name="top_wrist_joint" type="continuous">
    <axis xyz="0 1 0" />
    <parent link="elbow" />
    <child link="top_wrist" />
    <origin rpy="0 0 0" xyz="0.0 0 0.20994" />
  </joint>


  <!--######################################################################-->
  <gazebo reference="arm_base">
    <material>Gazebo/Green</material>
  </gazebo>
  <gazebo reference="bicep">
    <material>Gazebo/Green</material>
  </gazebo>
  <gazebo reference="bottom_wrist">
    <material>Gazebo/Green</material>
  </gazebo>
  <gazebo reference="elbow">
    <material>Gazebo/Green</material>
  </gazebo>
  <gazebo reference="top_wrist">
    <material>Gazebo/Green</material>
  </gazebo>


  <gazebo>
    <plugin name="joint_state_publisher" filename="libgazebo_ros_joint_state_publisher.so">
      <update_rate>30</update_rate>
      <joint_name>arm_base_joint</joint_name>
      <joint_name>shoulder_joint</joint_name>
      <joint_name>bottom_wrist_joint</joint_name>
      <joint_name>elbow_joint</joint_name>
      <joint_name>bottom_wrist_joint</joint_name>
      <!--
      -->
    </plugin>
  </gazebo>
  

  <!--######################################################################-->


</robot>